Workbook
Name INVTYPE: [1]master!$H$2:$H$5
Name POS: [1]master!$G$2:$G$38
Name RATE: [1]master!$F$2:$F$8
Name RCHARGE: [1]master!$C$2:$C$3

Sheet DELHI 3B
A1: GSTR-3B [See rule 61(5)]
A4: GSTIN | B4: 07AABCG4768K1Z9 | D4: Year | F4: 2026-27
A5: Legal name of the registered person | B5: Godfrey Phillips India Limited | D5: Month | F5: Apr-26
A7: 3.1 Details of Outward Supplies and inward supplies liable to reverse charge
A8: Nature of Supplies | B8: Total Taxable value | C8: Integrated Tax | D8: Central Tax | E8: State/UT Tax | F8: Cess
A9: 1 | B9: 2 | C9: 3 | D9: 4 | E9: 5 | F9: 6
A10: (a) Outward Taxable supplies (other than zero rated, nil rated and exempted) | B10: =Outward!AL1 -> 89063008 | C10: =Outward!AQ1 -> 9519863.6 | D10: =Outward!AO1 -> 3255738.9 | E10: =D10 -> 3255738.9 | F10: =Outward!AT1+Outward!AV1 -> 0
A11: (b) Outward Taxable supplies (zero rated )
A12: (c) Other Outward Taxable supplies (Nil rated, exempted)
A13: (d) Inward supplies (liable to reverse charge) | B13: =SUMIF(Inward!AZ:AZ,G13,Inward!AI:AI) -> 1948857 | C13: =SUMIF(Inward!AZ:AZ,G13,Inward!AN:AN) -> 20600.1 | D13: =SUMIF(Inward!AZ:AZ,G13,Inward!AM:AM) -> 165097.08 | E13: =D13 -> 165097.08 | F13: 0 | G13: Y
A14: (e) Non-GST Outward supplies
A15: Total | B15: =SUM(B10:B14) -> 91011865 | C15: =SUM(C10:C14) -> 9540463.7 | D15: =SUM(D10:D14) -> 3420836 | E15: =SUM(E10:E14) -> 3420836 | F15: =SUM(F10:F14) -> 0
A17: 4. Eligible ITC
A18: Details | B18: Integrated Tax | C18: Central Tax | D18: State/UT Tax | E18: Cess
A19: 1 | B19: 2 | C19: 3 | D19: 4 | E19: 5
A20: (A) ITC Available (Whether in full or part)
A21: (1) Import of goods | B21: 0
A22: (2) Import of services
A23: (3) Inward supplies liable to reverse charge (other than 1 &2 above) | B23: =SUMIFS(Inward!AN:AN,Inward!AZ:AZ,G23,Inward!AY:AY,'DELHI 3B'!F23) -> 8100 | C23: =SUMIFS(Inward!AM:AM,Inward!AZ:AZ,G23,Inward!AY:AY,'DELHI 3B'!F23) -> 147097.08 | D23: =C23 -> 147097.08 | E23: 0 | F23: Y | G23: Y
A24: (4) Inward supplies from ISD
A25: (5) All other ITC | B25: =SUMIF(Inward!AZ:AZ,G25,Inward!AN:AN) -> 165504.08 | C25: =SUMIF(Inward!AZ:AZ,G25,Inward!AL:AL) -> 1160702.4 | D25: =C25 -> 1160702.4 | E25: =SUMIF(Inward!AZ:AZ,G25,Inward!AR:AR) -> 0 | F25: Y | G25: N
A26: TOTAL ITC A | B26: =B21+B22+B23+B24+B25 -> 173604.08 | C26: =C21+C22+C23+C24+C25 -> 1307799.4 | D26: =D21+D22+D23+D24+D25 -> 1307799.4 | E26: =E21+E22+E23+E24+E25 -> 0
A27: (B) ITC Reversed
A28: (1) As per Rule 42 & 43 of SGST/CGST rules | B28: =SUMIFS(Inward!AN:AN,Inward!AY:AY,F28,Inward!AZ:AZ,'DELHI 3B'!G28) -> 101580.48 | C28: =SUMIFS(Inward!AM:AM,Inward!AY:AY,F28,Inward!AZ:AZ,'DELHI 3B'!G28) -> 116074.59 | D28: =C28 -> 116074.59 | E28: =SUMIFS(Inward!AR:AR,Inward!AZ:AZ,G28,Inward!AY:AY,'DELHI 3B'!F28) -> 0 | F28: N | G28: N
A29: (2) Others | B29: ='ITC REVERSAL'!C5+'ITC Revers & Reclaim - 180 Days'!R8+'ITC REVERSAL'!I4 -> 8388.3983 | C29: ='ITC REVERSAL'!D5+'ITC Revers - 180 Days'!P17+'ITC REVERSAL'!J4 -> 33233.122 | D29: ='ITC REVERSAL'!E5+'ITC Revers - 180 Days'!Q17+'ITC REVERSAL'!K4 -> 33233.122 | E29: 0 | F29: STT Reversal & Other
A30: TOTAL ITC B | B30: =B28+B29 -> 109968.88 | C30: =C28+C29 -> 149307.71 | D30: =D28+D29 -> 149307.71 | E30: =E28+E29 -> 0
A31: (C) Net ITC Available (A)-(B) | B31: =B26-B30 -> 63635.202 | C31: =C26-C30 -> 1158491.7 | D31: =D26-D30 -> 1158491.7 | E31: =E26-E30 -> 0
A32: (D) Ineligible ITC
A33: (1) As per section 17(5) of CGST//SGST Act | B33: 0 | C33: 0 | D33: =C33 -> 0 | E33: 0
A34: (2) Others | B34: 0 | C34: 0 | D34: =C34 -> 0 | E34: 0
B35: =B26-B28-'ITC Revers & Reclaim - 180 Days'!R8 -> 72023.6 | C35: =C26-C28-'ITC Revers & Reclaim - 180 Days'!S8 -> 1191724.9 | D35: =D26-D28-'ITC Revers & Reclaim - 180 Days'!T8 -> 1191724.9 | E35: =E26-E28 -> 0
B36: =B25-B28 -> 63923.6 | C36: =C25-C28 -> 1044627.8 | D36: =D25-D28 -> 1044627.8 | E36: =E25-E28 -> 0
A37: 5. Values of exempt, Nil-rated and non-GST inward supplies
A38: Nature of supplies | C38: Inter-State supplies | D38: Intra-state supplies
A39: 1 | C39: 2 | D39: 3
A40: From a supplier under composition scheme, Exempt and Nil rated supply | C40: 0 | D40: 0
A41: Non GST supply | D41: 0
A42: Total | C42: =SUM(C40:C41) -> 0 | D42: =SUM(D40:D41) -> 0
A45: 5.1 Interest & late fee payable
A46: Description | B46: Integrated Tax | C46: Central Tax | D46: State/UT Tax | E46: Cess
...

Sheet ITC REVERSAL
B2: ITC Reversal on Security Transaction | H2: ITC Reversal - Non Recov Trx claimed in 3b as Recov now Reversed
B3: Month | C3: IGST | D3: CGST | E3: SGST | F3: Total | H3: Month | I3: IGST | J3: CGST | K3: SGST | L3: Total
B4: Mar | C4: 8388.3983 | D4: 33233.122 | E4: 33233.122 | F4: =SUM(C4:E4) -> 74854.641 | I4: =-AJ9 -> 0 | J4: =-AH9 -> 0 | K4: =-AI9 -> 0 | L4: =SUM(I4:K4) -> 0
B5: Total | C5: =SUM(C4:C4) -> 8388.3983 | D5: =SUM(D4:D4) -> 33233.122 | E5: =SUM(E4:E4) -> 33233.122 | F5: =SUM(F4:F4) -> 74854.641 | H5: Total | I5: =SUM(I4:I4) -> 0 | J5: =SUM(J4:J4) -> 0 | K5: =SUM(K4:K4) -> 0 | L5: =SUM(L4:L4) -> 0
AH9: =SUM(AH11) -> 0 | AI9: =SUM(AI11) -> 0 | AJ9: =SUM(AJ11) -> 0
A10: Document Type | B10: Trx Category | C10: Org Id | D10: Rec OU | E10: IO Name | F10: GST Inv No | G10: IO Location | H10: FP REGN | I10: ENTITY CODE | J10: EVENT TYPE CODE | K10: SOURCE | L10: TRX TYPE | M10: ACCOUNTING DATE | N10: TRX NUMBER | O10: TRX ID | P10: TRX DATE | Q10: PARTY TYPE | R10: PARTY NUMBER | S10: PARTY NAME | T10: PARTY SITE NAME | U10: TP REGNNO | V10: TRX UOM | W10: UNIT PRICE | X10: TRX QTY | Y10: LINE AMT | Z10: REGIME | AA10: SUPPLIER INVOICE NUM | AB10: SUPPLIER INVOICE DATE | AC10: ITEM CODE | AD10: HSN/SACCODE | AE10: ITEM DES | AF10: GST TAXABLE AMT | AG10: GST TAX RATE | AH10: SGST | AI10: CGST | AJ10: IGST | AK10: IGST IMPORT | AL10: UTGST | AM10: CESS1 RATE | AN10: CESS1 | AO10: CESS2 RATE | AP10: CESS2 | AQ10: TCS RATE/ADHOC | AR10: TCS AMOUNT | AS10: OTHER TAX | AT10: TOTAL AMT | AU10: TRX REC | AV10: TRX SELF | AW10: EXPENSE | AX10: VOUCHARNO | AY10: TAX CATEGORY | AZ10: ITC CATEGORY | BA10: Custom BOE No | BB10: Custom BOE Date | BC10: Port Code | BD10: IRN Status | BE10: State Code | BF10: State Name | BG10: GSTIN & INV | BH10: Total Tax | BI10: V-Lookuop | BJ10: Diff | BK10: Remark | BL10: TRX ID | BM10: ITC Type | BO10: Inv Year | BP10: 2B Year

Sheet ITC Revers - 180 Days

Sheet ITC Revers & Reclaim - 180 Days

Sheet Outward
AL1: =SUBTOTAL(9,AL3:AL46) -> 89063008 | AO1: =SUBTOTAL(9,AO3:AO46) -> 3255738.9 | AP1: =SUBTOTAL(9,AP3:AP46) -> 3255738.9 | AQ1: =SUBTOTAL(9,AQ3:AQ46) -> 9519863.6 | AR1: =SUBTOTAL(9,AR3:AR46) -> 0 | AT1: =SUBTOTAL(9,AT3:AT46) -> 0 | AV1: =SUBTOTAL(9,AV3:AV46) -> 0
A2: Document Type | B2: Trx Category | C2: Org Id | D2: Rec OU | E2: IO Name | F2: GST Inv No | G2: EXC Inv No | H2: IO Location | I2: FP REGN | J2: ENTITY CODE | K2: APPLICATION NAME | L2: EVENT TYPE CODE | M2: SOURCE | N2: TRX TYPE | O2: ACCOUNTING DATE | P2: TRX NUMBER | Q2: TRX ID | R2: TRX DATE | S2: PARTY TYPE | T2: PARTY NUMBER | U2: PARTY NAME | V2: PARTY SITE NAME | W2: TP REGNNAME | X2: TP REGNNO | Y2: TRX UOM | Z2: MRP | AA2: UNIT PRICE | AB2: TRX QTY | AC2: LINE AMT | AD2: REGIME | AE2: ITEM CODE | AF2: HSN/SACCODE | AG2: ITEM DESCRIPTION | AH2: CIGARETTE LENGTH | AI2: NCCD | AJ2: BED | AK2: Deemed Taxable Value Per "M" | AL2: GST TAXABLE AMT | AM2: Tax Type | AN2: GST TAX RATE | AO2: SGST | AP2: CGST | AQ2: IGST | AR2: UTGST | AS2: CESS1 RATE | AT2: CESS1 | AU2: CESS2 RATE | AV2: CESS2 | AW2: TCS RATE/ADHOC | AX2: TCS AMOUNT | AY2: OTHER TAX | AZ2: TOTAL INVOICE AMOUNT | BA2: TRX REC | BB2: TRX SELF | BC2: REVENUE | BD2: CREDITNOTE INV NUM | BE2: TAX CATEGORY | BF2: ITC CATEGORY | BG2: EWAY BILL NUM | BH2: EWAY BILL DATE | BI2: IRN NUMBER | BJ2: IRN DATE
A3: Tax Invoice | B3: AR_INVOICE | C3: 107 | D3: Godfrey_Phillips_India_Limited_HO | E3: GPIL_HO_New_Delhi(Services) | F3: GPI-HOC260300032 | H3: HO New Friends Colony | I3: 07AABCG4768K1Z9 | J3: TRANSACTIONS | K3: Receivables | L3: INV_COMPLETE | O3: 46142 | P3: 11263000032 | Q3: 27210284 | R3: 46142 | S3: Customer | T3: 445074 | U3: Godfrey Phillips India Limited | V3: GPI -CUTTAK | W3: GSTIN | X3: 21AABCG4768K1ZJ | AA3: 243260 | AB3: 1 | AC3: 243260 | AD3: GST_India | AF3: 998599 | AG3: BUSINESS SUPPORT SERVICES CROSS CHARGED FOR THE PERIOD MAR-26 | AJ3: 0 | AK3: 0 | AL3: 243260 | AM3: Normal | AN3: 18 | AO3: 0 | AP3: 0 | AQ3: 43786.8 | AR3: 0 | AS3: 0 | AT3: 0 | AU3: 0 | AV3: 0 | AY3: 0 | AZ3: 287046.8 | BA3: Y | BB3: N | BC3: 11.7100.111.512110.0000.000000.0000.000000.000000.00000000 | BD3: GPI-HOC260300032 | BE3: HO_INTER-STATE_OTH_REC_18% | BF3: INPUT_SERVICE | BI3: 90ee7e29ba933c98780c9a9fe543aa5ba4b47efcc0666108cb4a627bc9f84b99 | BJ3: 46142.587 | BK3: B2B
A4: Tax Invoice | B4: AR_INVOICE | C4: 107 | D4: Godfrey_Phillips_India_Limited_HO | E4: GPIL_HO_New_Delhi(Services) | F4: GPI-HOC260300042 | H4: HO New Friends Colony | I4: 07AABCG4768K1Z9 | J4: TRANSACTIONS | K4: Receivables | L4: INV_COMPLETE | O4: 46142 | P4: 11263000042 | Q4: 27210352 | R4: 46142 | S4: Customer | T4: 2889 | U4: Godfrey Phillips India Limited, Chandigarh | V4: I112101 | W4: GSTIN | X4: 04AABCG4768K1ZF | AA4: 379724 | AB4: 1 | AC4: 379724 | AD4: GST_India | AF4: 998599 | AG4: BUSINESS SUPPORT SERVICES CROSS CHARGED FOR THE PERIOD MAR-26 | AJ4: 0 | AK4: 0 | AL4: 379724 | AM4: Normal | AN4: 18 | AO4: 0 | AP4: 0 | AQ4: 68350.32 | AR4: 0 | AS4: 0 | AT4: 0 | AU4: 0 | AV4: 0 | AY4: 0 | AZ4: 448074.32 | BA4: Y | BB4: N | BC4: 11.7100.111.512110.0000.000000.0000.000000.000000.00000000 | BD4: GPI-HOC260300042 | BE4: HO_INTER-STATE_OTH_REC_18% | BF4: INPUT_SERVICE | BI4: fa1944df608de037db4e0ebe405f00213244878d26b739a443e1d58dbf941b14 | BJ4: 46142.616 | BK4: B2B
A5: Tax Invoice | B5: AR_INVOICE | C5: 107 | D5: Godfrey_Phillips_India_Limited_HO | E5: GPIL_HO_New_Delhi(Services) | F5: GPI-HOC260300038 | H5: HO New Friends Colony | I5: 07AABCG4768K1Z9 | J5: TRANSACTIONS | K5: Receivables | L5: INV_COMPLETE | O5: 46142 | P5: 11263000038 | Q5: 27210294 | R5: 46142 | S5: Customer | T5: 445076 | U5: GODFREY PHILLIPS INDIA LIMITED | V5: GPI TAMIL NADU | W5: GSTIN | X5: 33AABCG4768K1ZE | AA5: 621770 | AB5: 1 | AC5: 621770 | AD5: GST_India | AF5: 998599 | AG5: BUSINESS SUPPORT SERVICES CROSS CHARGED FOR THE PERIOD MAR-26 | AJ5: 0 | AK5: 0 | AL5: 621770 | AM5: Normal | AN5: 18 | AO5: 0 | AP5: 0 | AQ5: 111918.6 | AR5: 0 | AS5: 0 | AT5: 0 | AU5: 0 | AV5: 0 | AY5: 0 | AZ5: 733688.6 | BA5: Y | BB5: N | BC5: 11.7100.111.512110.0000.000000.0000.000000.000000.00000000 | BD5: GPI-HOC260300038 | BE5: HO_INTER-STATE_OTH_REC_18% | BF5: INPUT_SERVICE | BI5: 0269c8365b7deac9cfdcf8c5611795bf1b73cf88592f09a278f8d0e30ec3f843 | BJ5: 46142.595 | BK5: B2B
A6: Tax Invoice | B6: AR_INVOICE | C6: 107 | D6: Godfrey_Phillips_India_Limited_HO | E6: GPIL_HO_New_Delhi(Services) | F6: GPI-HOC260300020 | H6: HO New Friends Colony | I6: 07AABCG4768K1Z9 | J6: TRANSACTIONS | K6: Receivables | L6: INV_COMPLETE | O6: 46141 | P6: 11263000020 | Q6: 27208567 | R6: 46141 | S6: Customer | T6: 866092 | U6: MODI STRATFORD ENTERPRISE MANAGEMENT PRIVATE LIMITED | V6: DELHI-24 | W6: GSTIN | X6: 07AAGCM2799F1Z6 | AA6: 3100 | AB6: 1 | AC6: 3100 | AD6: GST_India | AF6: 997212 | AG6: RENT PREMISES FOR 49,2 ND Floor, COMMUNITY CENTRE,FRIENDS COLONY, NEW DELHI FOR THE M/O APR-'26 | AJ6: 0 | AK6: 0 | AL6: 3100 | AM6: Normal | AN6: 18 | AO6: 279 | AP6: 279 | AQ6: 0 | AR6: 0 | AS6: 0 | AT6: 0 | AU6: 0 | AV6: 0 | AY6: 0 | AZ6: 3658 | BA6: Y | BB6: N | BC6: 11.7100.111.321110.2900.000000.0000.000000.000000.00000000 | BD6: GPI-HOC260300020 | BE6: HO_INTRA-STATE_OTH_REC_18% | BF6: INPUT_SERVICE | BI6: 412b6dbe20b3dd9dd49460f857a82465e70a1c73695ec895a389b4180eb680d3 | BJ6: 46141.666 | BK6: B2B
A7: Tax Invoice | B7: AR_INVOICE | C7: 107 | D7: Godfrey_Phillips_India_Limited_HO | E7: GPIL_HO_New_Delhi(Services) | F7: GPI-HOC260300009 | H7: HO New Friends Colony | I7: 07AABCG4768K1Z9 | J7: TRANSACTIONS | K7: Receivables | L7: INV_COMPLETE | O7: 46135 | P7: 11263000009 | Q7: 27200710 | R7: 46135 | S7: Customer | T7: 1242122 | U7: PHILIP MORRIS INDIA TRADING PRIVATE LIMITED (FORMERLY IPM INDIA WHOLESALE TRADING PVT. LTD.) | V7: 08EB_CIG_GURUG_0001 | W7: GSTIN | X7: 06AACCI0642K2ZQ | AA7: 2069542 | AB7: 1 | AC7: 2069542 | AD7: GST_India | AF7: 998371 | AG7: Being amount of AVF styudy 17 additional cities q1 | AJ7: 0 | AK7: 0 | AL7: 2069542 | AM7: Normal | AN7: 18 | AO7: 0 | AP7: 0 | AQ7: 372517.56 | AR7: 0 | AS7: 0 | AT7: 0 | AU7: 0 | AV7: 0 | AY7: 0 | AZ7: 2442059.6 | BA7: Y | BB7: N | BC7: 11.7100.111.416101.2500.000000.0000.000000.000000.00000000 | BD7: GPI-HOC260300009 | BE7: HO_INTER-STATE_OTH_REC_18% | BF7: INPUT_SERVICE | BI7: a0b2e6bd10d57b94df969e33db9198e583cd8804785eecc23e3811e4bcf2a0a7 | BJ7: 46135.537 | BK7: B2B
A8: Tax Invoice | B8: AR_INVOICE | C8: 107 | D8: Godfrey_Phillips_India_Limited_HO | E8: GPIL_HO_New_Delhi(Services) | F8: GPI-HOC260300024 | H8: HO New Friends Colony | I8: 07AABCG4768K1Z9 | J8: TRANSACTIONS | K8: Receivables | L8: INV_COMPLETE | O8: 46142 | P8: 11263000024 | Q8: 27210244 | R8: 46142 | S8: Customer | T8: 446063 | U8: GODFREY PHILLIPS INDIA LIMITED | V8: GPI UTTARKHAND | W8: GSTIN | X8: 05AABCG4768K1ZD | AA8: 50230 | AB8: 1 | AC8: 50230 | AD8: GST_India | AF8: 998599 | AG8: BUSINESS SUPPORT SERVICES CROSS CHARGED FOR THE PERIOD MAR-26 | AJ8: 0 | AK8: 0 | AL8: 50230 | AM8: Normal | AN8: 18 | AO8: 0 | AP8: 0 | AQ8: 9041.4 | AR8: 0 | AS8: 0 | AT8: 0 | AU8: 0 | AV8: 0 | AY8: 0 | AZ8: 59271.4 | BA8: Y | BB8: N | BC8: 11.7100.111.512110.0000.000000.0000.000000.000000.00000000 | BD8: GPI-HOC260300024 | BE8: HO_INTER-STATE_OTH_REC_18% | BF8: INPUT_SERVICE | BI8: c860f615853261f188f1c404191373b9e3ef5bb45cc2c0e0683b8e3ed3e7d889 | BJ8: 46142.553 | BK8: B2B
A9: Tax Invoice | B9: AR_INVOICE | C9: 107 | D9: Godfrey_Phillips_India_Limited_HO | E9: GPIL_HO_New_Delhi(Services) | F9: GPI-HOC260300033 | H9: HO New Friends Colony | I9: 07AABCG4768K1Z9 | J9: TRANSACTIONS | K9: Receivables | L9: INV_COMPLETE | O9: 46142 | P9: 11263000033 | Q9: 27210289 | R9: 46142 | S9: Customer | T9: 823087 | U9: Godfrey Phillips India Limited, Chhattisgarh | V9: Chhattisgarh_HO | W9: GSTIN | X9: 22AABCG4768K1ZH | AA9: 465529 | AB9: 1 | AC9: 465529 | AD9: GST_India | AF9: 998599 | AG9: BUSINESS SUPPORT SERVICES CROSS CHARGED FOR THE PERIOD MAR-26 | AJ9: 0 | AK9: 0 | AL9: 465529 | AM9: Normal | AN9: 18 | AO9: 0 | AP9: 0 | AQ9: 83795.22 | AR9: 0 | AS9: 0 | AT9: 0 | AU9: 0 | AV9: 0 | AY9: 0 | AZ9: 549324.22 | BA9: Y | BB9: N | BC9: 11.7100.111.512110.0000.000000.0000.000000.000000.00000000 | BD9: GPI-HOC260300033 | BE9: HO_INTER-STATE_OTH_REC_18% | BF9: INPUT_SERVICE | BI9: b11c81bfd051685118061537a33378085dd099874934b2e26748da9c2ac1e20a | BJ9: 46142.587 | BK9: B2B
A10: Tax Invoice | B10: AR_INVOICE | C10: 107 | D10: Godfrey_Phillips_India_Limited_HO | E10: GPIL_HO_New_Delhi(Services) | F10: GPI-HOC260300039 | H10: HO New Friends Colony | I10: 07AABCG4768K1Z9 | J10: TRANSACTIONS | K10: Receivables | L10: INV_COMPLETE | O10: 46142 | P10: 11263000039 | Q10: 27210340 | R10: 46142 | S10: Customer | T10: 2892 | U10: Godfrey Phillips India Limited, Hyderabad | V10: I112001 | W10: GSTIN | X10: 36AABCG4768K1Z8 | AA10: 1057196 | AB10: 1 | AC10: 1057196 | AD10: GST_India | AF10: 998599 | AG10: BUSINESS SUPPORT SERVICES CROSS CHARGED FOR THE PERIOD MAR-26 | AJ10: 0 | AK10: 0 | AL10: 1057196 | AM10: Normal | AN10: 18 | AO10: 0 | AP10: 0 | AQ10: 190295.28 | AR10: 0 | AS10: 0 | AT10: 0 | AU10: 0 | AV10: 0 | AY10: 0 | AZ10: 1247491.3 | BA10: Y | BB10: N | BC10: 11.7100.111.512110.0000.000000.0000.000000.000000.00000000 | BD10: GPI-HOC260300039 | BE10: HO_INTER-STATE_OTH_REC_18% | BF10: INPUT_SERVICE | BI10: cf63d7b74bb26569ab0910c6e6b4c7e48020d1c35e7f801e71cc4b87d97de310 | BJ10: 46142.608 | BK10: B2B
A11: Tax Invoice | B11: AR_INVOICE | C11: 107 | D11: Godfrey_Phillips_India_Limited_HO | E11: GPIL_HO_New_Delhi(Services) | F11: GPI-HOC260300043 | H11: HO New Friends Colony | I11: 07AABCG4768K1Z9 | J11: TRANSACTIONS | K11: Receivables | L11: INV_COMPLETE | O11: 46142 | P11: 11263000043 | Q11: 27210504 | R11: 46142 | S11: Customer | T11: 1006109 | U11: GODFREY PHILLIPS INDIA LIMITED (HR) | V11: 08EB_ALL_DELHI_0004 | W11: GSTIN | X11: 06AABCG4768K1ZB | AA11: 641574 | AB11: 1 | AC11: 641574 | AD11: GST_India | AF11: 998599 | AG11: BUSINESS SUPPORT SERVICES CROSS CHARGED FOR THE PERIOD MAR-26 | AJ11: 0 | AK11: 0 | AL11: 641574 | AM11: Normal | AN11: 18 | AO11: 0 | AP11: 0 | AQ11: 115483.32 | AR11: 0 | AS11: 0 | AT11: 0 | AU11: 0 | AV11: 0 | AY11: 0 | AZ11: 757057.32 | BA11: Y | BB11: N | BC11: 11.7100.111.512110.0000.000000.0000.000000.000000.00000000 | BD11: GPI-HOC260300043 | BE11: HO_INTER-STATE_OTH_REC_18% | BF11: INPUT_SERVICE | BI11: 683241a1e4737ca483c28547f9b7401d539cb1ef305c31be28b2e77e6c008af4 | BJ11: 46142.664 | BK11: B2B
A12: Tax Invoice | B12: AR_INVOICE | C12: 107 | D12: Godfrey_Phillips_India_Limited_HO | E12: GPIL_HO_New_Delhi(Services) | F12: GPI-HOC260300017 | H12: HO New Friends Colony | I12: 07AABCG4768K1Z9 | J12: TRANSACTIONS | K12: Receivables | L12: INV_COMPLETE | O12: 46141 | P12: 11263000017 | Q12: 27208564 | R12: 46141 | S12: Customer | T12: 5137 | U12: Bina Fashion N Food (P) Ltd | V12: Ho45 | W12: GSTIN | X12: 07AABCB5582A1Z1 | AA12: 246500 | AB12: 1 | AC12: 246500 | AD12: GST_India | AF12: 997212 | AG12: RENT PREMISES FOR GROUND FLOOR,4,COMMUNITY CENTRE,FRIENDS COLONY,NEW DELHI-110025 2465 SQ.FT FOR THE M/O APR-'26 | AJ12: 0 | AK12: 0 | AL12: 246500 | AM12: Normal | AN12: 18 | AO12: 22185 | AP12: 22185 | AQ12: 0 | AR12: 0 | AS12: 0 | AT12: 0 | AU12: 0 | AV12: 0 | AY12: 0 | AZ12: 290870 | BA12: Y | BB12: N | BC12: 11.7100.111.321110.2900.000000.0000.000000.000000.00000000 | BD12: GPI-HOC260300017 | BE12: HO_INTRA-STATE_OTH_REC_18% | BF12: INPUT_SERVICE | BI12: 8483eb2ee008d604d62eb296a596609f01c6f41996cd78330bf9c3231458be73 | BJ12: 46141.662 | BK12: B2B
A13: Tax Invoice | B13: AR_INVOICE | C13: 107 | D13: Godfrey_Phillips_India_Limited_HO | E13: GPIL_HO_New_Delhi(Services) | F13: GPI-HOC260300008 | H13: HO New Friends Colony | I13: 07AABCG4768K1Z9 | J13: TRANSACTIONS | K13: Receivables | L13: INV_COMPLETE | O13: 46134 | P13: 11263000008 | Q13: 27198626 | R13: 46134 | S13: Customer | T13: 1242122 | U13: PHILIP MORRIS INDIA TRADING PRIVATE LIMITED (FORMERLY IPM INDIA WHOLESALE TRADING PVT. LTD.) | V13: 08EB_CIG_GURUG_0001 | W13: GSTIN | X13: 06AACCI0642K2ZQ | AA13: 2985024 | AB13: 1 | AC13: 2985024 | AD13: GST_India | AF13: 998371 | AG13: Being amount of AVF Study 5FC Q1JFM | AJ13: 0 | AK13: 0 | AL13: 2985024 | AM13: Normal | AN13: 18 | AO13: 0 | AP13: 0 | AQ13: 537304.32 | AR13: 0 | AS13: 0 | AT13: 0 | AU13: 0 | AV13: 0 | AY13: 0 | AZ13: 3522328.3 | BA13: Y | BB13: N | BC13: 11.7100.111.416101.2500.000000.0000.000000.000000.00000000 | BD13: GPI-HOC260300008 | BE13: HO_INTER-STATE_OTH_REC_18% | BF13: INPUT_SERVICE | BI13: b4bfe34d16f4e5b2e17d203831a50dce31440e36f90d67945e9c9da29e0e8d8b | BJ13: 46134.631 | BK13: B2B
A14: Manual Regime Entry | B14: MANUAL_ENTRY | C14: 107 | D14: Godfrey_Phillips_India_Limited_HO | E14: GPIL_HO_New_Delhi(Services) | F14: GPI-HOC260300066 | H14: HO New Friends Colony | I14: 07AABCG4768K1Z9 | J14: MANUAL_ENTRY | K14: Asia/Pacific Localizations | L14: MANUAL_ENTRY_CREATE | M14: Form Entry | N14: LIABILITY | O14: 46142 | P14: 108621355 | Q14: 108621355 | R14: 46142 | S14: CUSTOMER | T14: 2894 | U14: Godfrey Phillips India Limited, Ho | V14: HOC_ISD | X14: 07AABCG4768K3Z7 | AA14: 0 | AB14: 0 | AC14: 15615254 | AD14: GST_India | AE14: Services_ISD | AF14: 998346 | AG14: Services_ISD | AJ14: 0 | AK14: 0 | AL14: 15615254 | AM14: Normal | AN14: 18 | AO14: 1405372.8 | AP14: 1405372.8 | AQ14: 0 | AR14: 0 | AS14: 0 | AT14: 0 | AU14: 0 | AV14: 0 | AY14: 0 | AZ14: 18425999 | BA14: Y | BB14: N | BC14: 11.7100.111.512120.0000.000000.0000.000000.000000.00000000 | BI14: a541de5602a0b6a8e2003437be64d0e2e63b3ff9065d1760969b1bab75b9f4d0 | BJ14: 46142.843 | BK14: B2B
A15: Tax Invoice | B15: AR_INVOICE | C15: 107 | D15: Godfrey_Phillips_India_Limited_HO | E15: GPIL_HO_New_Delhi(Services) | F15: GPI-HOC260300031 | H15: HO New Friends Colony | I15: 07AABCG4768K1Z9 | J15: TRANSACTIONS | K15: Receivables | L15: INV_COMPLETE | O15: 46142 | P15: 11263000031 | Q15: 27210283 | R15: 46142 | S15: Customer | T15: 445073 | U15: GODFREY PHILLIPS INDIA LIMITED | V15: GPI-JHARKHAND | W15: GSTIN | X15: 20AABCG4768K1ZL | AA15: 226700 | AB15: 1 | AC15: 226700 | AD15: GST_India | AF15: 998599 | AG15: BUSINESS SUPPORT SERVICES CROSS CHARGED FOR THE PERIOD MAR-26 | AJ15: 0 | AK15: 0 | AL15: 226700 | AM15: Normal | AN15: 18 | AO15: 0 | AP15: 0 | AQ15: 40806 | AR15: 0 | AS15: 0 | AT15: 0 | AU15: 0 | AV15: 0 | AY15: 0 | AZ15: 267506 | BA15: Y | BB15: N | BC15: 11.7100.111.512110.0000.000000.0000.000000.000000.00000000 | BD15: GPI-HOC260300031 | BE15: HO_INTER-STATE_OTH_REC_18% | BF15: INPUT_SERVICE | BI15: ebd7cf4d39f52b49f38c34188d5cf8ce4452b6144ded985de6b759edda3a3af7 | BJ15: 46142.585 | BK15: B2B
A16: Tax Invoice | B16: AR_INVOICE | C16: 107 | D16: Godfrey_Phillips_India_Limited_HO | E16: GPIL_HO_New_Delhi(Services) | F16: GPI-HOC260300001 | H16: HO New Friends Colony | I16: 07AABCG4768K1Z9 | J16: TRANSACTIONS | K16: Receivables | L16: INV_COMPLETE | O16: 46113 | P16: 11263000001 | Q16: 27165327 | R16: 46113 | S16: Customer | T16: 1044110 | U16: Godfrey Phillips India Limited, Jaipur | V16: HOJGM | W16: GSTIN | X16: 23AABCG4768K1ZF | AA16: 57185.63 | AB16: 1 | AC16: 57185.63 | AD16: GST_India | AF16: 84713010 | AG16: Dell laptop vide asset no.227618 (S.NO.17W3TB4) | AJ16: 0 | AK16: 0 | AL16: 57185.63 | AM16: Normal | AN16: 18 | AO16: 0 | AP16: 0 | AQ16: 10293.41 | AR16: 0 | AS16: 0 | AT16: 0 | AU16: 0 | AV16: 0 | AY16: 0 | AZ16: 67479.04 | BA16: Y | BB16: N | BC16: 11.7100.111.511050.0000.000000.0000.000000.000000.00000000 | BD16: GPI-HOC260300001 | BE16: HO_INTER-STATE_OTH_REC_18% | BF16: CAPITAL_GOODS | BI16: 6bad53248db99ce5a76d4107c44cb79180273639c0af18f5c9955f81584a64ae | BJ16: 46113.506 | BK16: B2B
A17: Tax Invoice | B17: AR_INVOICE | C17: 107 | D17: Godfrey_Phillips_India_Limited_HO | E17: GPIL_HO_New_Delhi(Services) | F17: GPI-HOC260300005 | H17: HO New Friends Colony | I17: 07AABCG4768K1Z9 | J17: TRANSACTIONS | K17: Receivables | L17: INV_COMPLETE | O17: 46129 | P17: 11263000005 | Q17: 27192922 | R17: 46129 | S17: Customer | T17: 469067 | U17: EMPLOYEE | V17: EMPLOYEE- DELHI | AA17: 3375 | AB17: 1 | AC17: 3375 | AD17: GST_India | AF17: 84713010 | AG17: Dell Latitude Asset no.111591 Mr.Ashutosh (gst assessable value Rs.13500 | AJ17: 0 | AK17: 0 | AL17: 13500 | AM17: Normal | AN17: 18 | AO17: 1215 | AP17: 1215 | AQ17: 0 | AR17: 0 | AS17: 0 | AT17: 0 | AU17: 0 | AV17: 0 | AY17: 0 | AZ17: 5805 | BA17: Y | BB17: N | BC17: 11.7100.111.511500.0000.000000.0000.000000.000000.00000000 | BD17: GPI-HOC260300005 | BE17: HO_INTRA-STATE_OTH_REC_18% | BF17: CAPITAL_GOODS | BK17: B2CS
A18: Tax Invoice | B18: AR_INVOICE | C18: 107 | D18: Godfrey_Phillips_India_Limited_HO | E18: GPIL_HO_New_Delhi(Services) | F18: GPI-HOC260300018 | H18: HO New Friends Colony | I18: 07AABCG4768K1Z9 | J18: TRANSACTIONS | K18: Receivables | L18: INV_COMPLETE | O18: 46141 | P18: 11263000018 | Q18: 27208565 | R18: 46141 | S18: Customer | T18: 5137 | U18: Bina Fashion N Food (P) Ltd | V18: Ho45 | W18: GSTIN | X18: 07AABCB5582A1Z1 | AA18: 285000 | AB18: 1 | AC18: 285000 | AD18: GST_India | AF18: 997212 | AG18: RENT PREMISES FOR GROUND FLOOR,49, COMMUNITY CENTRE, NEW FRIENDS COLONY, NEW DELHI-110025 AREA 1900 SQFT FOR THE M/O APR-'26 | AJ18: 0 | AK18: 0 | AL18: 285000 | AM18: Normal | AN18: 18 | AO18: 25650 | AP18: 25650 | AQ18: 0 | AR18: 0 | AS18: 0 | AT18: 0 | AU18: 0 | AV18: 0 | AY18: 0 | AZ18: 336300 | BA18: Y | BB18: N | BC18: 11.7100.111.321110.2900.000000.0000.000000.000000.00000000 | BD18: GPI-HOC260300018 | BE18: HO_INTRA-STATE_OTH_REC_18% | BF18: INPUT_SERVICE | BI18: addb2878081b8fa351cfce675717d9baa8278c22fb874fa2c45162140cd74ac6 | BJ18: 46141.664 | BK18: B2B
A19: Tax Invoice | B19: AR_INVOICE | C19: 107 | D19: Godfrey_Phillips_India_Limited_HO | E19: GPIL_HO_New_Delhi(Services) | F19: GPI-HOC260300030 | H19: HO New Friends Colony | I19: 07AABCG4768K1Z9 | J19: TRANSACTIONS | K19: Receivables | L19: INV_COMPLETE | O19: 46142 | P19: 11263000030 | Q19: 27210282 | R19: 46142 | S19: Customer | T19: 3311 | U19: Godfrey Phillips India Limited, Kolkata | V19: I111601 | W19: GSTIN | X19: 19AABCG4768K1Z4 | AA19: 248566 | AB19: 1 | AC19: 248566 | AD19: GST_India | AF19: 998599 | AG19: BUSINESS SUPPORT SERVICES CROSS CHARGED FOR THE PERIOD MAR-26 | AJ19: 0 | AK19: 0 | AL19: 248566 | AM19: Normal | AN19: 18 | AO19: 0 | AP19: 0 | AQ19: 44741.88 | AR19: 0 | AS19: 0 | AT19: 0 | AU19: 0 | AV19: 0 | AY19: 0 | AZ19: 293307.88 | BA19: Y | BB19: N | BC19: 11.7100.111.512110.0000.000000.0000.000000.000000.00000000 | BD19: GPI-HOC260300030 | BE19: HO_INTER-STATE_OTH_REC_18% | BF19: INPUT_SERVICE | BI19: 4db2621fcb42dab14cb2b6f13655acda3666344b3c592e41099df98540e0f855 | BJ19: 46142.583 | BK19: B2B
A20: Tax Invoice | B20: AR_INVOICE | C20: 107 | D20: Godfrey_Phillips_India_Limited_HO | E20: GPIL_HO_New_Delhi(Services) | F20: GPI-HOC260300040 | H20: HO New Friends Colony | I20: 07AABCG4768K1Z9 | J20: TRANSACTIONS | K20: Receivables | L20: INV_COMPLETE | O20: 46142 | P20: 11263000040 | Q20: 27210345 | R20: 46142 | S20: Customer | T20: 2893 | U20: GODFREY PHILLIPS INDIA LIMITED, GUNTUR | V20: I111401 | W20: GSTIN | X20: 37AABCG4768K1Z6 | AA20: 4288144 | AB20: 1 | AC20: 4288144 | AD20: GST_India | AF20: 998599 | AG20: BUSINESS SUPPORT SERVICES CROSS CHARGED FOR THE PERIOD MAR-26 | AJ20: 0 | AK20: 0 | AL20: 4288144 | AM20: Normal | AN20: 18 | AO20: 0 | AP20: 0 | AQ20: 771865.92 | AR20: 0 | AS20: 0 | AT20: 0 | AU20: 0 | AV20: 0 | AY20: 0 | AZ20: 5060009.9 | BA20: Y | BB20: N | BC20: 11.7100.111.512110.0000.000000.0000.000000.000000.00000000 | BD20: GPI-HOC260300040 | BE20: HO_INTER-STATE_OTH_REC_18% | BF20: INPUT_SERVICE | BI20: fdd6fdeba31ee4f01676945f84c3b967d0cc6975723786eb7e4c036ccad2f75d | BJ20: 46142.61 | BK20: B2B
A21: Tax Invoice | B21: AR_INVOICE | C21: 107 | D21: Godfrey_Phillips_India_Limited_HO | E21: GPIL_HO_New_Delhi(Services) | F21: GPI-HOC260300029 | H21: HO New Friends Colony | I21: 07AABCG4768K1Z9 | J21: TRANSACTIONS | K21: Receivables | L21: INV_COMPLETE | O21: 46142 | P21: 11263000029 | Q21: 27210281 | R21: 46142 | S21: Customer | T21: 445072 | U21: GODFREY PHILLIPS INDIA LIMITED | V21: GPI -ASSAM | W21: GSTIN | X21: 18AABCG4768K1Z6 | AA21: 96318 | AB21: 1 | AC21: 96318 | AD21: GST_India | AF21: 998599 | AG21: BUSINESS SUPPORT SERVICES CROSS CHARGED FOR THE PERIOD MAR-26 | AJ21: 0 | AK21: 0 | AL21: 96318 | AM21: Normal | AN21: 18 | AO21: 0 | AP21: 0 | AQ21: 17337.24 | AR21: 0 | AS21: 0 | AT21: 0 | AU21: 0 | AV21: 0 | AY21: 0 | AZ21: 113655.24 | BA21: Y | BB21: N | BC21: 11.7100.111.512110.0000.000000.0000.000000.000000.00000000 | BD21: GPI-HOC260300029 | BE21: HO_INTER-STATE_OTH_REC_18% | BF21: INPUT_SERVICE | BI21: 27bbf7a0070406f35b823b2d097dcd71978d6d8027de59ab1bfc311e621b80c5 | BJ21: 46142.581 | BK21: B2B
A22: Tax Invoice | B22: AR_INVOICE | C22: 107 | D22: Godfrey_Phillips_India_Limited_HO | E22: GPIL_HO_New_Delhi(Services) | F22: GPI-HOC260300011 | H22: HO New Friends Colony | I22: 07AABCG4768K1Z9 | J22: TRANSACTIONS | K22: Receivables | L22: INV_COMPLETE | O22: 46141 | P22: 11263000011 | Q22: 27208486 | R22: 46141 | S22: Customer | T22: 56078 | U22: INTERNATIONAL RESEARCH PARK LABORATORIES LTD | V22: INT4CC | AA22: 5000 | AB22: 1 | AC22: 5000 | AD22: GST_India | AF22: 997212 | AG22: RENT PREMISES FOR IST FLOOR, 4,COMMMUNITY CENTRE,NFC,N.DELHI FOR THE M/O APR-'26 | AJ22: 0 | AK22: 0 | AL22: 5000 | AM22: Normal | AN22: 18 | AO22: 450 | AP22: 450 | AQ22: 0 | AR22: 0 | AS22: 0 | AT22: 0 | AU22: 0 | AV22: 0 | AY22: 0 | AZ22: 5900 | BA22: Y | BB22: N | BC22: 11.7100.111.321110.2900.000000.0000.000000.000000.00000000 | BD22: GPI-HOC260300011 | BE22: HO_INTRA-STATE_OTH_REC_18% | BF22: B2C | BK22: B2CS
A23: Tax Invoice | B23: AR_INVOICE | C23: 107 | D23: Godfrey_Phillips_India_Limited_HO | E23: GPIL_HO_New_Delhi(Services) | F23: GPI-HOC260300004 | H23: HO New Friends Colony | I23: 07AABCG4768K1Z9 | J23: TRANSACTIONS | K23: Receivables | L23: INV_COMPLETE | O23: 46128 | P23: 11263000004 | Q23: 27190294 | R23: 46128 | S23: Customer | T23: 2892 | U23: Godfrey Phillips India Limited, Hyderabad | V23: I112001 | W23: GSTIN | X23: 36AABCG4768K1Z8 | AA23: 81783.1 | AB23: 1 | AC23: 81783.1 | AD23: GST_India | AF23: 84713010 | AG23: HP LAPTOP S.NO.5CD6106BJ0 (ASSET NO.278586) | AJ23: 0 | AK23: 0 | AL23: 81783.1 | AM23: Normal | AN23: 18 | AO23: 0 | AP23: 0 | AQ23: 14720.96 | AR23: 0 | AS23: 0 | AT23: 0 | AU23: 0 | AV23: 0 | AY23: 0 | AZ23: 96504.06 | BA23: Y | BB23: N | BC23: 11.7100.111.511100.0000.000000.0000.000000.000000.00000000 | BD23: GPI-HOC260300004 | BE23: HO_INTER-STATE_OTH_REC_18% | BF23: CAPITAL_GOODS | BI23: f3e10e29f82bb3b9a53b56bb22a49de1eba23d8154b2d1289272b5848803356d | BJ23: 46128.533 | BK23: B2B
A24: Credit Memo | B24: AR_INVOICE | C24: 107 | D24: Godfrey_Phillips_India_Limited_HO | E24: GPIL_HO_New_Delhi(Services) | F24: GPI-HOC260300001-01-APR-26 | H24: HO New Friends Colony | I24: 07AABCG4768K1Z9 | J24: TRANSACTIONS | K24: Receivables | L24: CM_COMPLETE | O24: 46113 | P24: 11261000001 | Q24: 27165331 | R24: 46113 | S24: Customer | T24: 1044110 | U24: Godfrey Phillips India Limited, Jaipur | V24: HOJGM | W24: GSTIN | X24: 23AABCG4768K1ZF | AA24: -57185.63 | AB24: 1 | AC24: -57185.63 | AD24: GST_India | AF24: 84713010 | AG24: CANCELLATION OF INVOICE NO.GPI/HOC260300001 (ASSET NO.227618) | AJ24: 0 | AK24: 0 | AL24: -57185.63 | AM24: Normal | AN24: 18 | AO24: 0 | AP24: 0 | AQ24: -10293.41 | AR24: 0 | AS24: 0 | AT24: 0 | AU24: 0 | AV24: 0 | AY24: 0 | AZ24: -67479.04 | BA24: Y | BB24: N | BC24: 11.7100.111.511050.0000.000000.0000.000000.000000.00000000 | BD24: GPI-HOC260200001 | BE24: HO_INTER-STATE_OTH_REC_18% | BF24: CAPITAL_GOODS | BI24: 8060ffbe52f2cc7c64cd919d7d678517a205864fd9793b127d837e0fc9c1b456 | BJ24: 46113.533 | BK24: B2B-CN
A25: Tax Invoice | B25: AR_INVOICE | C25: 107 | D25: Godfrey_Phillips_India_Limited_HO | E25: GPIL_HO_New_Delhi(Services) | F25: GPI-HOC260300021 | H25: HO New Friends Colony | I25: 07AABCG4768K1Z9 | J25: TRANSACTIONS | K25: Receivables | L25: INV_COMPLETE | O25: 46141 | P25: 11263000021 | Q25: 27208568 | R25: 46141 | S25: Customer | T25: 1052115 | U25: A AND V ZIPPERS PVT. LIMITED | V25: 08EB_ALL_DELHI_0007 | W25: GSTIN | X25: 07AADCA3655R1Z7 | AA25: 5000 | AB25: 1 | AC25: 5000 | AD25: GST_India | AF25: 997212 | AG25: RENT PREMISES FOR 2ND FLOOR,49, COMMUNITY CENTRE,NFC,N.DELHI 40 SQFT@125/- FOR THE M/O APR-'26 | AJ25: 0 | AK25: 0 | AL25: 5000 | AM25: Normal | AN25: 18 | AO25: 450 | AP25: 450 | AQ25: 0 | AR25: 0 | AS25: 0 | AT25: 0 | AU25: 0 | AV25: 0 | AY25: 0 | AZ25: 5900 | BA25: Y | BB25: N | BC25: 11.7100.111.321110.2900.000000.0000.000000.000000.00000000 | BD25: GPI-HOC260300021 | BE25: HO_INTRA-STATE_OTH_REC_18% | BF25: INPUT_SERVICE | BI25: e8e37ff586f2aab0e14f38d9b3bd4f473d3024f751fb6ae5783d79a5998c5fba | BJ25: 46141.668 | BK25: B2B
A26: Tax Invoice | B26: AR_INVOICE | C26: 107 | D26: Godfrey_Phillips_India_Limited_HO | E26: GPIL_HO_New_Delhi(Services) | F26: GPI-HOC260300019 | H26: HO New Friends Colony | I26: 07AABCG4768K1Z9 | J26: TRANSACTIONS | K26: Receivables | L26: INV_COMPLETE | O26: 46141 | P26: 11263000019 | Q26: 27208566 | R26: 46141 | S26: Customer | T26: 5137 | U26: Bina Fashion N Food (P) Ltd | V26: Ho45 | W26: GSTIN | X26: 07AABCB5582A1Z1 | AA26: 500000 | AB26: 1 | AC26: 500000 | AD26: GST_India | AF26: 997212 | AG26: RENT PREMISES FOR 2ND & 3RD FLOOR, 49, COMMUNITY CENTRE,FRIENDS COLONY , NEW DELHI-110025 AREA 4000 SQFT FOR THE M/O APR-'26 | AJ26: 0 | AK26: 0 | AL26: 500000 | AM26: Normal | AN26: 18 | AO26: 45000 | AP26: 45000 | AQ26: 0 | AR26: 0 | AS26: 0 | AT26: 0 | AU26: 0 | AV26: 0 | AY26: 0 | AZ26: 590000 | BA26: Y | BB26: N | BC26: 11.7100.111.321110.2900.000000.0000.000000.000000.00000000 | BD26: GPI-HOC260300019 | BE26: HO_INTRA-STATE_OTH_REC_18% | BF26: INPUT_SERVICE | BI26: bbf022a3da0bdd7fb98cfea252dce2c9fee214d3a6169a56eb4b9c0d4765bda1 | BJ26: 46141.666 | BK26: B2B
A27: Tax Invoice | B27: AR_INVOICE | C27: 107 | D27: Godfrey_Phillips_India_Limited_HO | E27: GPIL_HO_New_Delhi(Services) | F27: GPI-HOC260300002 | H27: HO New Friends Colony | I27: 07AABCG4768K1Z9 | J27: TRANSACTIONS | K27: Receivables | L27: INV_COMPLETE | O27: 46113 | P27: 11263000002 | Q27: 27165329 | R27: 46113 | S27: Customer | T27: 1045110 | U27: Godfrey Phillips India Limited, Jammu | V27: HOJBG | W27: GSTIN | X27: 01AABCG4768K1ZL | AA27: 50526 | AB27: 1 | AC27: 50526 | AD27: GST_India | AF27: 84713010 | AG27: Being amount of dell laptop vide asset no.201615 (Nitin Gupta) | AJ27: 0 | AK27: 0 | AL27: 50526 | AM27: Normal | AN27: 18 | AO27: 0 | AP27: 0 | AQ27: 9094.68 | AR27: 0 | AS27: 0 | AT27: 0 | AU27: 0 | AV27: 0 | AY27: 0 | AZ27: 59620.68 | BA27: Y | BB27: N | BC27: 11.7100.111.511250.0000.000000.0000.000000.000000.00000000 | BD27: GPI-HOC260300002 | BE27: HO_INTER-STATE_OTH_REC_18% | BF27: CAPITAL_GOODS | BI27: 1d0f50957afc2bbf15981ceefdf6919df62eb1aa189ff407681f554b1fdaea8c | BJ27: 46113.516 | BK27: B2B
A28: Tax Invoice | B28: AR_INVOICE | C28: 107 | D28: Godfrey_Phillips_India_Limited_HO | E28: GPIL_HO_New_Delhi(Services) | F28: GPI-HOC260300035 | H28: HO New Friends Colony | I28: 07AABCG4768K1Z9 | J28: TRANSACTIONS | K28: Receivables | L28: INV_COMPLETE | O28: 46142 | P28: 11263000035 | Q28: 27210291 | R28: 46142 | S28: Customer | T28: 446062 | U28: Godfrey Phillips India Limited | V28: GPI GOA | W28: GSTIN | X28: 30AABCG4768K1ZK | AA28: 99004 | AB28: 1 | AC28: 99004 | AD28: GST_India | AF28: 998599 | AG28: BUSINESS SUPPORT SERVICES CROSS CHARGED FOR THE PERIOD MAR-26 | AJ28: 0 | AK28: 0 | AL28: 99004 | AM28: Normal | AN28: 18 | AO28: 0 | AP28: 0 | AQ28: 17820.72 | AR28: 0 | AS28: 0 | AT28: 0 | AU28: 0 | AV28: 0 | AY28: 0 | AZ28: 116824.72 | BA28: Y | BB28: N | BC28: 11.7100.111.512110.0000.000000.0000.000000.000000.00000000 | BD28: GPI-HOC260300035 | BE28: HO_INTER-STATE_OTH_REC_18% | BF28: INPUT_SERVICE | BI28: ab165f6a9243ab3283f5013b6586a65b4d06b7fe408b230d392ebd7250e08445 | BJ28: 46142.591 | BK28: B2B
A29: Tax Invoice | B29: AR_INVOICE | C29: 107 | D29: Godfrey_Phillips_India_Limited_HO | E29: GPIL_HO_New_Delhi(Services) | F29: GPI-HOC260300012 | H29: HO New Friends Colony | I29: 07AABCG4768K1Z9 | J29: TRANSACTIONS | K29: Receivables | L29: INV_COMPLETE | O29: 46141 | P29: 11263000012 | Q29: 27208487 | R29: 46141 | S29: Customer | T29: 156023 | U29: RAJPUTANA DEVELOPERS LIMITED | V29: 53 CC | W29: GSTIN | X29: 07AAECR2482G1ZD | AA29: 11000 | AB29: 1 | AC29: 11000 | AD29: GST_India | AF29: 997212 | AG29: RENT PREMISES FOR 14,OMAXE SQAURE, JASOLA, NEW DELHI FOR THE M/O APR-'26 | AJ29: 0 | AK29: 0 | AL29: 11000 | AM29: Normal | AN29: 18 | AO29: 990 | AP29: 990 | AQ29: 0 | AR29: 0 | AS29: 0 | AT29: 0 | AU29: 0 | AV29: 0 | AY29: 0 | AZ29: 12980 | BA29: Y | BB29: N | BC29: 11.7100.111.321110.2900.000000.0000.000000.000000.00000000 | BD29: GPI-HOC260300012 | BE29: HO_INTRA-STATE_OTH_REC_18% | BF29: INPUT_SERVICE | BI29: 5158c19577192d526170ffe5a5f51a18273f61bbe5cf3d68b4522f8d9185b506 | BJ29: 46141.649 | BK29: B2B
A30: Tax Invoice | B30: AR_INVOICE | C30: 107 | D30: Godfrey_Phillips_India_Limited_HO | E30: GPIL_HO_New_Delhi(Services) | F30: GPI-HOC260300041 | H30: HO New Friends Colony | I30: 07AABCG4768K1Z9 | J30: TRANSACTIONS | K30: Receivables | L30: INV_COMPLETE | O30: 46142 | P30: 11263000041 | Q30: 27210351 | R30: 46142 | S30: Customer | T30: 445067 | U30: GODFREY PHILLIPS INDIA LIMITED | V30: GPI MOHALI | W30: GSTIN | X30: 03AABCG4768K1ZH | AA30: 462317 | AB30: 1 | AC30: 462317 | AD30: GST_India | AF30: 998599 | AG30: BUSINESS SUPPORT SERVICES CROSS CHARGED FOR THE PERIOD MAR-26 | AJ30: 0 | AK30: 0 | AL30: 462317 | AM30: Normal | AN30: 18 | AO30: 0 | AP30: 0 | AQ30: 83217.06 | AR30: 0 | AS30: 0 | AT30: 0 | AU30: 0 | AV30: 0 | AY30: 0 | AZ30: 545534.06 | BA30: Y | BB30: N | BC30: 11.7100.111.512110.0000.000000.0000.000000.000000.00000000 | BD30: GPI-HOC260300041 | BE30: HO_INTER-STATE_OTH_REC_18% | BF30: INPUT_SERVICE | BI30: 672bd21e04b274039757f9ef2196cba8edad1f325101a1fdd8748915be5bd8f0 | BJ30: 46142.614 | BK30: B2B
A31: Tax Invoice | B31: AR_INVOICE | C31: 107 | D31: Godfrey_Phillips_India_Limited_HO | E31: GPIL_HO_New_Delhi(Services) | F31: GPI-HOC260300006 | H31: HO New Friends Colony | I31: 07AABCG4768K1Z9 | J31: TRANSACTIONS | K31: Receivables | L31: INV_COMPLETE | O31: 46133 | P31: 11263000006 | Q31: 27199210 | R31: 46133 | S31: Customer | T31: 1077115 | U31: FERRERO INDIA PVT LTD-PUNE | V31: 08EB_ALL_PUNE_0001 | W31: GSTIN | X31: 27AAACF8110B1Z8 | AA31: 329343.3 | AB31: 1 | AC31: 329343.3 | AD31: GST_India | AF31: 998599 | AG31: Being amount of other support services for ferrero fusion Q4 FY26 | AJ31: 0 | AK31: 0 | AL31: 329343.3 | AM31: Normal | AN31: 18 | AO31: 0 | AP31: 0 | AQ31: 59281.79 | AR31: 0 | AS31: 0 | AT31: 0 | AU31: 0 | AV31: 0 | AY31: 0 | AZ31: 388625.09 | BA31: Y | BB31: N | BC31: 11.7100.371.416101.2500.000000.0000.000000.000000.00000000 | BD31: GPI-HOC260300006 | BE31: HO_INTER-STATE_OTH_REC_18% | BF31: INPUT_SERVICE | BI31: eb694a307d43ef7c9ad79cd32033351d2c065acd2740bf9b9b2352c292a8d475 | BJ31: 46133.797 | BK31: B2B
A32: Tax Invoice | B32: AR_INVOICE | C32: 107 | D32: Godfrey_Phillips_India_Limited_HO | E32: GPIL_HO_New_Delhi(Services) | F32: GPI-HOC260300025 | H32: HO New Friends Colony | I32: 07AABCG4768K1Z9 | J32: TRANSACTIONS | K32: Receivables | L32: INV_COMPLETE | O32: 46142 | P32: 11263000025 | Q32: 27210245 | R32: 46142 | S32: Customer | T32: 445069 | U32: GODFREY PHILLIPS INDIA LIMITED | V32: GPI JAIPUR | W32: GSTIN | X32: 08AABCG4768K1Z7 | AA32: 1495479 | AB32: 1 | AC32: 1495479 | AD32: GST_India | AF32: 998599 | AG32: BUSINESS SUPPORT SERVICES CROSS CHARGED FOR THE PERIOD MAR-26 | AJ32: 0 | AK32: 0 | AL32: 1495479 | AM32: Normal | AN32: 18 | AO32: 0 | AP32: 0 | AQ32: 269186.22 | AR32: 0 | AS32: 0 | AT32: 0 | AU32: 0 | AV32: 0 | AY32: 0 | AZ32: 1764665.2 | BA32: Y | BB32: N | BC32: 11.7100.111.512110.0000.000000.0000.000000.000000.00000000 | BD32: GPI-HOC260300025 | BE32: HO_INTER-STATE_OTH_REC_18% | BF32: INPUT_SERVICE | BI32: 6d4f37769b8339f491f3b3d120057f66cdf1131907f50cc3e5652c35d04ab850 | BJ32: 46142.553 | BK32: B2B
A33: Tax Invoice | B33: AR_INVOICE | C33: 107 | D33: Godfrey_Phillips_India_Limited_HO | E33: GPIL_HO_New_Delhi(Services) | F33: GPI-HOC260300034 | H33: HO New Friends Colony | I33: 07AABCG4768K1Z9 | J33: TRANSACTIONS | K33: Receivables | L33: INV_COMPLETE | O33: 46142 | P33: 11263000034 | Q33: 27210290 | R33: 46142 | S33: Customer | T33: 445075 | U33: Godfrey Phillips India Limited | V33: GPI INDORE | W33: GSTIN | X33: 23AABCG4768K1ZF | AA33: 901643 | AB33: 1 | AC33: 901643 | AD33: GST_India | AF33: 998599 | AG33: BUSINESS SUPPORT SERVICES CROSS CHARGED FOR THE PERIOD MAR-26 | AJ33: 0 | AK33: 0 | AL33: 901643 | AM33: Normal | AN33: 18 | AO33: 0 | AP33: 0 | AQ33: 162295.74 | AR33: 0 | AS33: 0 | AT33: 0 | AU33: 0 | AV33: 0 | AY33: 0 | AZ33: 1063938.7 | BA33: Y | BB33: N | BC33: 11.7100.111.512110.0000.000000.0000.000000.000000.00000000 | BD33: GPI-HOC260300034 | BE33: HO_INTER-STATE_OTH_REC_18% | BF33: INPUT_SERVICE | BI33: 3287af05dc718a3825d3212fb712505177eabc9b6b6e4bd8f2ebbf0f4c626a52 | BJ33: 46142.589 | BK33: B2B
A34: Tax Invoice | B34: AR_INVOICE | C34: 107 | D34: Godfrey_Phillips_India_Limited_HO | E34: GPIL_HO_New_Delhi(Services) | F34: GPI-HOC260300022 | H34: HO New Friends Colony | I34: 07AABCG4768K1Z9 | J34: TRANSACTIONS | K34: Receivables | L34: INV_COMPLETE | O34: 46142 | P34: 11263000022 | Q34: 27210238 | R34: 46142 | S34: Customer | T34: 445065 | U34: Godfrey Phillips India Limited | V34: jammu | W34: GSTIN | X34: 01AABCG4768K1ZL | AA34: 1151268 | AB34: 1 | AC34: 1151268 | AD34: GST_India | AF34: 998599 | AG34: BUSINESS SUPPORT SERVICES CROSS CHARGED FOR THE PERIOD MAR-26 | AJ34: 0 | AK34: 0 | AL34: 1151268 | AM34: Normal | AN34: 18 | AO34: 0 | AP34: 0 | AQ34: 207228.24 | AR34: 0 | AS34: 0 | AT34: 0 | AU34: 0 | AV34: 0 | AY34: 0 | AZ34: 1358496.2 | BA34: Y | BB34: N | BC34: 11.7100.111.512110.0000.000000.0000.000000.000000.00000000 | BD34: GPI-HOC260300022 | BE34: HO_INTER-STATE_OTH_REC_18% | BF34: INPUT_SERVICE | BI34: 354f0f0e296b7f1b3388a52b8a97e1998d0a082eabf1a913480fabcef6664bfa | BJ34: 46142.666 | BK34: B2B
... A41: Tax Invoice | B41: AR_INVOICE | C41: 107 | D41: Godfrey_Phillips_India_Limited_HO | E41: GPIL_HO_New_Delhi(Services) | F41: GPI-HOC260300023 | H41: HO New Friends Colony | I41: 07AABCG4768K1Z9 | J41: TRANSACTIONS | K41: Receivables | L41: INV_COMPLETE | O41: 46142 | P41: 11263000023 | Q41: 27210243 | R41: 46142 | S41: Customer | T41: 679080 | U41: GODFREY PHILLIPS INDIA LIMITED | V41: GODFREY-LADAKH | W41: GSTIN | X41: 38AABCG4768K1Z4 | AA41: 15454 | AB41: 1 | AC41: 15454 | AD41: GST_India | AF41: 998599 | AG41: BUSINESS SUPPORT SERVICES CROSS CHARGED FOR THE PERIOD MAR-26 | AJ41: 0 | AK41: 0 | AL41: 15454 | AM41: Normal | AN41: 18 | AO41: 0 | AP41: 0 | AQ41: 2781.72 | AR41: 0 | AS41: 0 | AT41: 0 | AU41: 0 | AV41: 0 | AY41: 0 | AZ41: 18235.72 | BA41: Y | BB41: N | BC41: 11.7100.111.512110.0000.000000.0000.000000.000000.00000000 | BD41: GPI-HOC260300023 | BE41: HO_INTER-STATE_OTH_REC_18% | BF41: INPUT_SERVICE | BI41: 753a435e541c04fac29f51fc211127f1e8448773e9b2971650aea831823b00e5 | BJ41: 46142.551 | BK41: B2B
A42: Manual Regime Entry | B42: MANUAL_ENTRY | C42: 107 | D42: Godfrey_Phillips_India_Limited_HO | E42: GPIL_HO_New_Delhi(Services) | F42: GPI-HOC260300070 | H42: HO New Friends Colony | I42: 07AABCG4768K1Z9 | J42: MANUAL_ENTRY | K42: Asia/Pacific Localizations | L42: MANUAL_ENTRY_CREATE | M42: Form Entry | N42: LIABILITY | O42: 46142 | P42: 108636040 | Q42: 108636040 | R42: 46142 | S42: CUSTOMER | T42: 2894 | U42: Godfrey Phillips India Limited, Ho | V42: HOC_ISD | X42: 07AABCG4768K3Z7 | AA42: 0 | AB42: 0 | AC42: 19283523 | AD42: GST_India | AE42: Services_ISD | AF42: 998346 | AG42: Services_ISD | AJ42: 0 | AK42: 0 | AL42: 19283523 | AM42: Normal | AN42: 18 | AO42: 1735517.1 | AP42: 1735517.1 | AQ42: 0 | AR42: 0 | AS42: 0 | AT42: 0 | AU42: 0 | AV42: 0 | AY42: 0 | AZ42: 22754557 | BA42: Y | BB42: N | BC42: 11.7100.111.512120.0000.000000.0000.000000.000000.00000000 | BI42: 8a08358c4e559433d403614a5c015a88e36c840b1de36ce67db84028b2f70e7e | BJ42: 46142.899 | BK42: B2B
A43: Tax Invoice | B43: AR_INVOICE | C43: 107 | D43: Godfrey_Phillips_India_Limited_HO | E43: GPIL_HO_New_Delhi(Services) | F43: GPI-HOC260300007 | H43: HO New Friends Colony | I43: 07AABCG4768K1Z9 | J43: TRANSACTIONS | K43: Receivables | L43: INV_COMPLETE | O43: 46133 | P43: 11263000007 | Q43: 27199220 | R43: 46133 | S43: Customer | T43: 1242122 | U43: PHILIP MORRIS INDIA TRADING PRIVATE LIMITED (FORMERLY IPM INDIA WHOLESALE TRADING PVT. LTD.) | V43: 08EB_CIG_GURUG_0001 | W43: GSTIN | X43: 06AACCI0642K2ZQ | AA43: 209913 | AB43: 1 | AC43: 209913 | AD43: GST_India | AF43: 999792 | AG43: Being amount of cost of credit m/o feb-26 | AJ43: 0 | AK43: 0 | AL43: 209913 | AM43: Normal | AN43: 18 | AO43: 0 | AP43: 0 | AQ43: 37784.34 | AR43: 0 | AS43: 0 | AT43: 0 | AU43: 0 | AV43: 0 | AY43: 0 | AZ43: 247697.34 | BA43: Y | BB43: N | BC43: 11.7100.111.321912.2900.000000.0000.000000.000000.00000000 | BD43: GPI-HOC260300007 | BE43: HO_INTER-STATE_OTH_REC_18% | BF43: INPUT_SERVICE | BI43: 9397213257517241871f6c5dca7c4b2c5974c24da4e19df228f454630610056c | BJ43: 46133.801 | BK43: B2B
A44: Tax Invoice | B44: AR_INVOICE | C44: 107 | D44: Godfrey_Phillips_India_Limited_HO | E44: GPIL_HO_New_Delhi(Services) | F44: GPI-HOC260300010 | H44: HO New Friends Colony | I44: 07AABCG4768K1Z9 | J44: TRANSACTIONS | K44: Receivables | L44: INV_COMPLETE | O44: 46141 | P44: 11263000010 | Q44: 27208814 | R44: 46141 | S44: Customer | T44: 1242122 | U44: PHILIP MORRIS INDIA TRADING PRIVATE LIMITED (FORMERLY IPM INDIA WHOLESALE TRADING PVT. LTD.) | V44: 08EB_CIG_GURUG_0001 | W44: GSTIN | X44: 06AACCI0642K2ZQ | AA44: 13537544 | AB44: 1 | AC44: 13537544 | AD44: GST_India | AF44: 999792 | AG44: Being amount of reimbursement of cost of credit M/O April-26 | AJ44: 0 | AK44: 0 | AL44: 13537544 | AM44: Normal | AN44: 18 | AO44: 0 | AP44: 0 | AQ44: 2436757.9 | AR44: 0 | AS44: 0 | AT44: 0 | AU44: 0 | AV44: 0 | AY44: 0 | AZ44: 15974302 | BA44: Y | BB44: N | BC44: 11.7100.111.321912.2900.000000.0000.000000.000000.00000000 | BD44: GPI-HOC260300010 | BE44: HO_INTER-STATE_OTH_REC_18% | BF44: INPUT_SERVICE | BI44: f1f23a362dc5166de5a5c5399e4ec3f84f728480c1066368fe7558bfbc42582e | BJ44: 46147.51 | BK44: B2B
A45: Tax Invoice | B45: AR_INVOICE | C45: 107 | D45: Godfrey_Phillips_India_Limited_HO | E45: GPIL_HO_New_Delhi(Services) | F45: GPI-HOC260300026 | H45: HO New Friends Colony | I45: 07AABCG4768K1Z9 | J45: TRANSACTIONS | K45: Receivables | L45: INV_COMPLETE | O45: 46142 | P45: 11263000026 | Q45: 27210253 | R45: 46142 | S45: Customer | T45: 2886 | U45: Godfrey Phillips India Limited, Ahmedabad | V45: I111901 | W45: GSTIN | X45: 24AABCG4768K1ZD | AA45: 1933792 | AB45: 1 | AC45: 1933792 | AD45: GST_India | AF45: 998599 | AG45: BUSINESS SUPPORT SERVICES CROSS CHARGED FOR THE PERIOD MAR-26 | AJ45: 0 | AK45: 0 | AL45: 1933792 | AM45: Normal | AN45: 18 | AO45: 0 | AP45: 0 | AQ45: 348082.56 | AR45: 0 | AS45: 0 | AT45: 0 | AU45: 0 | AV45: 0 | AY45: 0 | AZ45: 2281874.6 | BA45: Y | BB45: N | BC45: 11.7100.111.512110.0000.000000.0000.000000.000000.00000000 | BD45: GPI-HOC260300026 | BE45: HO_INTER-STATE_OTH_REC_18% | BF45: INPUT_SERVICE | BI45: 9676d458cd4b6a7741a07c71e3761152179b1f6802ebe1f89f030f7f22947400 | BJ45: 46142.556 | BK45: B2B
A46: Tax Invoice | B46: AR_INVOICE | C46: 107 | D46: Godfrey_Phillips_India_Limited_HO | E46: GPIL_HO_New_Delhi(Services) | F46: GPI-HOC260300037 | H46: HO New Friends Colony | I46: 07AABCG4768K1Z9 | J46: TRANSACTIONS | K46: Receivables | L46: INV_COMPLETE | O46: 46142 | P46: 11263000037 | Q46: 27210293 | R46: 46142 | S46: Customer | T46: 436061 | U46: GODFREY PHILLIPS INDIA LIMITED | V46: GPI BANGLORE | W46: GSTIN | X46: 29AABCG4768K2Z2 | AA46: 601705 | AB46: 1 | AC46: 601705 | AD46: GST_India | AF46: 998599 | AG46: BUSINESS SUPPORT SERVICES CROSS CHARGED FOR THE PERIOD MAR-26 | AJ46: 0 | AK46: 0 | AL46: 601705 | AM46: Normal | AN46: 18 | AO46: 0 | AP46: 0 | AQ46: 108306.9 | AR46: 0 | AS46: 0 | AT46: 0 | AU46: 0 | AV46: 0 | AY46: 0 | AZ46: 710011.9 | BA46: Y | BB46: N | BC46: 11.7100.111.512110.0000.000000.0000.000000.000000.00000000 | BD46: GPI-HOC260300037 | BE46: HO_INTER-STATE_OTH_REC_18% | BF46: INPUT_SERVICE | BI46: 0c4a8c9290d108b1b25069c56bb6cdb6c971115061bb4c9a0dd797e8b4c84aed | BJ46: 46142.595 | BK46: B2B

Sheet Pivat
K1: GSTIN & INV | L1: PR | M1: 2B | N1: DIFF
K2: 06AACCL4494J1Z8LNC/25-26/5110 | L2: 10296.59 | M2: 10122.11 | N2: 174
A3: Row Labels | B3: Sum of IGST | C3: Sum of SGST | D3: Sum of CGST | E3: Sum of CESS1 | F3: Total | H3: YEAR | I3: Amount | K3: 27AACCN6194P1ZP272612BP05AFT995 | L3: 328.4 | M3: 289 | N3: 39
A4: RCM-Not Matched | B4: 20600.1 | C4: 165097.08 | D4: 165097.08 | E4: 0 | F4: =SUM(B4:E4) -> 350794.26 | H4: FY 2025-26 | I4: 531023.64 | K4: 07AACCN6194P2ZQ072612BP04ACB413 | L4: 412.76 | M4: 375 | N4: 38
A5: RCM Non Rec | B5: 12500.1 | C5: 18000 | D5: 18000 | E5: 0 | F5: =SUM(B5:E5) -> 48500.1 | H5: FY 2026-27 | I5: 1956379.4 | K5: 07AAACB2894G1ZPMF2707I000063444 | L5: 7790.66 | M5: 8534.42 | N5: -744
A6: RCM Rec | B6: 8100 | C6: 147097.08 | D6: 147097.08 | E6: 0 | F6: =SUM(B6:E6) -> 302294.16 | I6: =SUM(I4:I5) -> 2487403
A7: Fwd - Matched | B7: 165504.08 | C7: 1160702.4 | D7: 1160702.4 | E7: 0 | F7: =SUM(B7:E7) -> 2486908.8
A8: Fwd Rec | B8: 63923.6 | C8: 1044627.8 | D8: 1044627.8 | E8: 0 | F8: =SUM(B8:E8) -> 2153179.1
A9: Fwd Non Rec | B9: 101580.48 | C9: 116074.59 | D9: 116074.59 | E9: 0 | F9: =SUM(B9:E9) -> 333729.66
A10: Grand Total | B10: 186104.18 | C10: 1325799.4 | D10: 1325799.4 | E10: 0 | F10: =SUM(F4:F9) -> 5675406.1
K12: Total - Difference | L12: =SUM(L2:L10) -> 18828.41 | M12: =SUM(M2:M10) -> 19320.53 | N12: =SUM(N2:N10) -> -493
E17: As per Books | F17: =F7 -> 2486908.8
E18: As per 2B | F18: =I6 -> 2487403
E19: Diffrence | F19: =F17-F18 -> -494.21 | G19: Refer O12

Sheet Inward
AI1: =SUBTOTAL(9,AI3:AI312) -> 15828442 | AL1: =SUBTOTAL(9,AL3:AL312) -> 1325799.4 | AM1: =SUBTOTAL(9,AM3:AM312) -> 1325799.4 | AN1: =SUBTOTAL(9,AN3:AN312) -> 186104.18 | AP1: =SUBTOTAL(9,AP3:AP312) -> 0 | AR1: =SUBTOTAL(9,AR3:AR312) -> 0 | AT1: =SUBTOTAL(9,AT3:AT312) -> 0 | AX1: =SUBTOTAL(9,AX3:AX312) -> 19025684 | BL1: =SUBTOTAL(9,BL3:BL312) -> 2837703.1
A2: Document Type | B2: Trx Category | C2: Org Id | D2: Rec OU | E2: IO Name | F2: GST Inv No | G2: IO Location | H2: FP REGN | I2: ENTITY CODE | J2: EVENT TYPE CODE | K2: SOURCE | L2: TRX TYPE | M2: ACCOUNTING DATE | N2: TRX NUMBER | O2: TRX ID | P2: TRX DATE | Q2: PARTY TYPE | R2: PARTY NUMBER | S2: PARTY NAME | T2: PARTY SITE NAME | U2: TP REGNNO | V2: TRX UOM | W2: MRP | X2: UNIT PRICE | Y2: TRX QTY | Z2: LINE AMT | AA2: REGIME | AB2: SUPPLIER INVOICE NUM | AC2: SUPPLIER INVOICE DATE | AD2: ITEM CODE | AE2: HSN/SACCODE | AF2: ITEM DES | AG2: NCCD | AH2: BED/CVD | AI2: GST TAXABLE AMT | AJ2: TAX TYPE | AK2: GST TAX RATE | AL2: SGST | AM2: CGST | AN2: IGST | AO2: IGST IMPORT | AP2: UTGST | AQ2: CESS1 RATE | AR2: CESS1 | AS2: CESS2 RATE | AT2: CESS2 | AU2: TCS RATE/ADHOC | AV2: TCS AMOUNT | AW2: OTHER TAX | AX2: TOTAL INVOICE AMOUNT | AY2: TRX REC | AZ2: TRX SELF | BA2: EXPENSE | BB2: VOUCHARNO | BC2: TAX CATEGORY | BD2: ITC CATEGORY | BE2: Custom BOE No | BF2: Custom BOE Date | BG2: Port Code | BH2: IRN Status | BI2: State Code | BJ2: State Name | BK2: GSTIN & INV | BL2: Total Tax | BM2: V-Lookuop | BN2: Diff | BO2: Remark | BP2: TRX ID | BQ2: ITC Type | BR2: 2B Year
A3: Payable Invoice | B3: AP_INVOICE | C3: 107 | D3: Godfrey_Phillips_India_Limited_HO | E3: GPIL_HO_New_Delhi(Services) | G3: HO New Friends Colony | H3: 07AABCG4768K1Z9 | I3: AP_INVOICES | J3: STANDARD CREATED | K3: Manual Invoice Entry | L3: STANDARD | M3: 46127 | N3: DFSI2600000412 | O3: 9158398 | P3: 46090 | Q3: Supplier | R3: 35671 | S3: DEUTSCHE CARS PRIVATE LIMITED | T3: Faridabad-OFF | U3: 06AAGCD4246E1ZX | V3: NOS | X3: 275 | Y3: 44 | Z3: 12100 | AA3: GST_India | AB3: DFSI2600000412 | AC3: 46121 | AD3: BUDMINTIND | AE3: 996200 | AF3: INTERIOR BEAUTIFICATION AND ENRICHMENT | AI3: 12100 | AJ3: Normal | AK3: 18 | AL3: 0 | AM3: 0 | AN3: 2178 | AO3: 0 | AP3: 0 | AQ3: 0 | AR3: 0 | AS3: 0 | AT3: 0 | AW3: 0 | AX3: 14278 | AY3: N | AZ3: N | BA3: 11.7100.111.414301.1011.111636.0007.000000.000000.00000000 | BB3: 1126100105 | BC3: HO_INTER-STATE_OTH_NON_REC_18% | BD3: INPUT_TDS_194C | BF3: Fwd Non Rec | BG3: Fwd - Matched | BH3: Yes | BI3: 07 | BJ3: Delhi | BK3: 06AAGCD4246E1ZXDFSI2600000412 | BL3: 2178 | BM3: 38182.88 | BN3: -36005 | BO3: Matched | BP3: 9158398 | BQ3: Fwd Non Rec | BR3: FY 2026-27 | BS3: 37
A4: Payable Invoice | B4: AP_INVOICE | C4: 107 | D4: Godfrey_Phillips_India_Limited_HO | E4: GPIL_HO_New_Delhi(Services) | G4: HO New Friends Colony | H4: 07AABCG4768K1Z9 | I4: AP_INVOICES | J4: STANDARD CREATED | K4: Manual Invoice Entry | L4: STANDARD | M4: 46127 | N4: DFSI2600000412 | O4: 9158398 | P4: 46090 | Q4: Supplier | R4: 35671 | S4: DEUTSCHE CARS PRIVATE LIMITED | T4: Faridabad-OFF | U4: 06AAGCD4246E1ZX | V4: NOS | X4: 1031.36 | Y4: 8 | Z4: 8250.88 | AA4: GST_India | AB4: DFSI2600000412 | AC4: 46121 | AD4: BUDMINTIND | AE4: 34029099 | AF4: OZONIZER | AI4: 8250.88 | AJ4: Normal | AK4: 18 | AL4: 0 | AM4: 0 | AN4: 1485.16 | AO4: 0 | AP4: 0 | AQ4: 0 | AR4: 0 | AS4: 0 | AT4: 0 | AW4: 0 | AX4: 9736.04 | AY4: N | AZ4: N | BA4: 11.7100.111.414301.1011.111636.0007.000000.000000.00000000 | BB4: 1126100105 | BC4: HO_INTER-STATE_OTH_NON_REC_18% | BD4: INPUT_TDS_194C | BF4: Fwd Non Rec | BG4: Fwd - Matched | BH4: Yes | BI4: 07 | BJ4: Delhi | BK4: 06AAGCD4246E1ZXDFSI2600000412 | BL4: 1485.16 | BM4: 38182.88 | BN4: -36698 | BO4: Matched | BP4: 9158398 | BQ4: Fwd Non Rec | BR4: FY 2026-27 | BS4: 37
A5: Payable Invoice | B5: AP_INVOICE | C5: 107 | D5: Godfrey_Phillips_India_Limited_HO | E5: GPIL_HO_New_Delhi(Services) | G5: HO New Friends Colony | H5: 07AABCG4768K1Z9 | I5: AP_INVOICES | J5: STANDARD CREATED | K5: Manual Invoice Entry | L5: STANDARD | M5: 46140 | N5: DFSI2600000751 | O5: 9174963 | P5: 46129 | Q5: Supplier | R5: 35671 | S5: DEUTSCHE CARS PRIVATE LIMITED | T5: Faridabad-OFF | U5: 06AAGCD4246E1ZX | V5: NOS | X5: 275 | Y5: 64 | Z5: 17600 | AA5: GST_India | AB5: DFSI2600000751 | AC5: 46129 | AD5: BUDMINTIND | AE5: 998729 | AF5: MECH CARE | AI5: 17600 | AJ5: Normal | AK5: 18 | AL5: 0 | AM5: 0 | AN5: 3168 | AO5: 0 | AP5: 0 | AQ5: 0 | AR5: 0 | AS5: 0 | AT5: 0 | AW5: 0 | AX5: 20768 | AY5: N | AZ5: N | BA5: 11.7100.111.414301.1000.100007.0007.000000.000000.00000000 | BB5: 1126100446 | BC5: HO_INTER-STATE_OTH_NON_REC_18% | BD5: INPUT_TDS_194C | BF5: Fwd Non Rec | BG5: Fwd - Matched | BH5: Yes | BI5: 07 | BJ5: Delhi | BK5: 06AAGCD4246E1ZXDFSI2600000751 | BL5: 3168 | BM5: 36494.74 | BN5: -33327 | BO5: Matched | BP5: 9174963 | BQ5: Fwd Non Rec | BR5: FY 2026-27 | BS5: 36
A6: Payable Invoice | B6: AP_INVOICE | C6: 107 | D6: Godfrey_Phillips_India_Limited_HO | E6: GPIL_HO_New_Delhi(Services) | G6: HO New Friends Colony | H6: 07AABCG4768K1Z9 | I6: AP_INVOICES | J6: STANDARD CREATED | K6: Manual Invoice Entry | L6: STANDARD | M6: 46127 | N6: MF2707I00063444 | O6: 9156749 | P6: 46115 | Q6: Supplier | R6: 6262 | S6: BHARTI AIRTEL LIMITED | T6: HO | U6: 07AAACB2894G1ZP | V6: NOS | X6: 1 | Y6: 3199 | Z6: 3199 | AA6: GST_India | AB6: MF2707I000063444 | AC6: 46115 | AD6: MISCELLENS | AE6: 998413 | AF6: AIRTEL MOBILE BILLS FOR THE MONTH OF MAR 2026 | AI6: 3199 | AJ6: Normal | AK6: 18 | AL6: 287.91 | AM6: 287.91 | AN6: 0 | AO6: 0 | AP6: 0 | AQ6: 0 | AR6: 0 | AS6: 0 | AT6: 0 | AW6: 0 | AX6: 3774.82 | AY6: Y | AZ6: N | BA6: 11.7100.111.420803.1000.000000.0007.000000.000000.00000000 | BB6: 1126100078 | BC6: HO_INTRA-STATE_OTH_REC_18% | BD6: INPUT_SERVICE | BF6: Fwd Rec | BG6: Fwd - Matched | BH6: Yes | BI6: 07 | BJ6: Delhi | BK6: 07AAACB2894G1ZPMF2707I000063444 | BL6: 575.82 | BM6: 8534.42 | BN6: -7959 | BO6: Matched | BP6: 9156749 | BQ6: Fwd Rec | BR6: FY 2026-27 | BS6: 17
A7: Payable Invoice | B7: AP_INVOICE | C7: 107 | D7: Godfrey_Phillips_India_Limited_HO | E7: GPIL_HO_New_Delhi(Services) | H7: 07AABCG4768K1Z9 | I7: AP_INVOICES | J7: STANDARD VALIDATED TAX | K7: IA | L7: STANDARD | M7: 46126 | N7: DLS2627000000593 | O7: 9155613 | P7: 46114 | Q7: Supplier | R7: 2770 | S7: CANON INDIA PVT. LTD. | T7: OKHLA | U7: 07AAACC4175D1Z0 | V7: NOS | X7: 1 | Y7: 2.8 | Z7: 2.8 | AA7: GST_India | AB7: DLS2627000000593 | AC7: 46114 | AD7: MISCELLENS | AE7: 84439952 | AF7: Supply of Tonernnk Spares along with Support Services | AI7: 2.8 | AJ7: Normal | AK7: 18 | AL7: 0.25 | AM7: 0.25 | AN7: 0 | AO7: 0 | AP7: 0 | AQ7: 0 | AR7: 0 | AS7: 0 | AT7: 0 | AW7: 0 | AX7: 3.3 | AY7: Y | AZ7: N | BA7: 11.7100.111.234010.0000.000000.0007.000000.000000.00000000 | BB7: 1126100063 | BC7: HO_INTRA-STATE_OTH_REC_18% | BD7: INPUT_SERVICE | BF7: Fwd Rec | BG7: Fwd - Matched | BH7: Yes | BI7: 07 | BJ7: Delhi | BK7: 07AAACC4175D1Z0DLS2627000000593 | BL7: 0.5 | BM7: 5381.62 | BN7: -5381 | BO7: Matched | BP7: 9155613 | BQ7: Fwd Rec | BR7: FY 2026-27 | BS7: 4
A8: Payable Invoice | B8: AP_INVOICE | C8: 107 | D8: Godfrey_Phillips_India_Limited_HO | E8: GPIL_HO_New_Delhi(Services) | H8: 07AABCG4768K1Z9 | I8: AP_INVOICES | J8: STANDARD VALIDATED TAX | K8: IA | L8: STANDARD | M8: 46133 | N8: LKS01-2627-00147 | O8: 9164641 | P8: 46122 | Q8: Supplier | R8: 3539 | S8: LAKSHMI KUMARAN AND SRIDHARAN | T8: NEW DELHI | U8: 07AAAFL1585H1ZD | V8: NOS | X8: 40000 | Y8: 1 | Z8: 40000 | AA8: GST_India | AB8: LKS01-2627-00147 | AC8: 46122 | AE8: 998212 | AF8: Towards professional fee for legal advice on the applicability of BIS- and EPR-related compliances to imports of primary AA and AAA alkaline batteries. | AI8: 40000 | AJ8: Normal | AK8: 18 | AL8: 3600 | AM8: 3600 | AN8: 0 | AO8: 0 | AP8: 0 | AQ8: 0 | AR8: 0 | AS8: 0 | AT8: 0 | AW8: 0 | AX8: 47200 | AY8: Y | AZ8: Y | BA8: 11.7100.111.416001.1009.000000.0007.000000.000000.00000000 | BB8: 1126100302 | BC8: HO_REV_CHARGE_REC_18% | BD8: INPUT_SERVICE | BF8: RCM Rec | BG8: RCM-Not Matched | BH8: Yes | BI8: 07 | BJ8: Delhi | BK8: 07AAAFL1585H1ZDLKS01-2627-001470 | BL8: 7200 | BM8: #N/A | BN8: #N/A | BO8: RCM | BP8: 9164641 | BQ8: RCM Rec | BR8: FY 2026-27 | BS8: 1
A9: Payable Invoice | B9: AP_INVOICE | C9: 107 | D9: Godfrey_Phillips_India_Limited_HO | E9: GPIL_HO_New_Delhi(Services) | H9: 07AABCG4768K1Z9 | I9: AP_INVOICES | J9: STANDARD VALIDATED TAX | K9: IA | L9: STANDARD | M9: 46136 | N9: SME/26-27/98 | O9: 9168298 | P9: 46127 | Q9: Supplier | R9: 3484 | S9: SREE MAHAVIR ENTERPRISES | T9: NEW DELHI | U9: 07AAOFS6787Q1ZV | V9: NOS | X9: 5000 | Y9: 1 | Z9: 5000 | AA9: GST_India | AB9: SME/26-27/98 | AC9: 46127 | AD9: BUDMINTIND | AE9: 998716 | AF9: Annual Maintainance Contract No. NEC SL2100 (38) EPABX System 2 Nos. Key Phone Period 01.04.2026 to 31.03.2027 | AI9: 5000 | AJ9: Normal | AK9: 18 | AL9: 450 | AM9: 450 | AN9: 0 | AO9: 0 | AP9: 0 | AQ9: 0 | AR9: 0 | AS9: 0 | AT9: 0 | AW9: 0 | AX9: 5900 | AY9: Y | AZ9: N | BA9: 11.7100.111.414401.1010.000000.0007.000000.000000.00000000 | BB9: 1126100391 | BC9: HO_INTRA-STATE_OTH_REC_18% | BD9: INPUT_SERVICE | BF9: Fwd Rec | BG9: Fwd - Matched | BH9: Yes | BI9: 07 | BJ9: Delhi | BK9: 07AAOFS6787Q1ZVSME/26-27/98 | BL9: 900 | BM9: 900 | BN9: 0 | BO9: Matched | BP9: 9168298 | BQ9: Fwd Rec | BR9: FY 2026-27 | BS9: 1
A10: Payable Invoice | B10: AP_INVOICE | C10: 107 | D10: Godfrey_Phillips_India_Limited_HO | E10: GPIL_HO_New_Delhi(Services) | H10: 07AABCG4768K1Z9 | I10: AP_INVOICES | J10: STANDARD VALIDATED TAX | K10: Manual Invoice Entry | L10: STANDARD | M10: 46142 | N10: GLMS0000059723 | O10: 9178440 | P10: 46089 | Q10: Supplier | R10: 40270 | S10: TATA AIA LIFE INSURANCE COMPANY LIMITED | T10: Thane | U10: 27AABCT3784C1ZD | X10: 0 | Y10: 0 | Z10: 1964.52 | AA10: GST_India | AB10: GLMS000000059723 | AC10: 46089 | AE10: 9971 | AF10: GTIL Policy Deletion of Members for the m/o Feb 2026 | AI10: 1964.52 | AJ10: Normal | AK10: 18 | AL10: 0 | AM10: 0 | AN10: 353.61 | AO10: 0 | AP10: 0 | AQ10: 0 | AR10: 0 | AS10: 0 | AT10: 0 | AW10: 0 | AX10: 2318.13 | AY10: N | AZ10: N | BA10: 11.7100.111.234010.0000.000000.0007.000000.000000.00000000 | BB10: 1126100570 | BC10: HO_INTER-STATE_OTH_NON_REC_18% | BD10: INPUT_SERVICE | BF10: Fwd Non Rec | BG10: Fwd - Matched | BH10: No | BI10: 07 | BJ10: Delhi | BK10: 27AABCT3784C1ZDGLMS000000059723 | BL10: 353.61 | BM10: 353.61 | BN10: 0 | BO10: Matched | BP10: 9178440 | BQ10: Fwd Non Rec | BR10: FY 2025-26 | BS10: 1
A11: Payable Invoice | B11: AP_INVOICE | C11: 107 | D11: Godfrey_Phillips_India_Limited_HO | E11: GPIL_HO_New_Delhi(Services) | H11: 07AABCG4768K1Z9 | I11: AP_INVOICES | J11: STANDARD VALIDATED TAX | K11: IA | L11: STANDARD | M11: 46126 | N11: DLS2627000000653 | O11: 9155610 | P11: 46114 | Q11: Supplier | R11: 2770 | S11: CANON INDIA PVT. LTD. | T11: OKHLA | U11: 07AAACC4175D1Z0 | V11: NOS | X11: 1 | Y11: 275 | Z11: 275 | AA11: GST_India | AB11: DLS2627000000653 | AC11: 46114 | AD11: MISCELLENS | AE11: 84439952 | AF11: Supply of Toner ink and Spares along with Support Services | AI11: 275 | AJ11: Normal | AK11: 18 | AL11: 24.75 | AM11: 24.75 | AN11: 0 | AO11: 0 | AP11: 0 | AQ11: 0 | AR11: 0 | AS11: 0 | AT11: 0 | AW11: 0 | AX11: 324.5 | AY11: Y | AZ11: N | BA11: 11.7100.111.234010.0000.000000.0007.000000.000000.00000000 | BB11: 1126100060 | BC11: HO_INTRA-STATE_OTH_REC_18% | BD11: INPUT_SERVICE | BF11: Fwd Rec | BG11: Fwd - Matched | BH11: Yes | BI11: 07 | BJ11: Delhi | BK11: 07AAACC4175D1Z0DLS2627000000653 | BL11: 49.5 | BM11: 489.18 | BN11: -440 | BO11: Matched | BP11: 9155610 | BQ11: Fwd Rec | BR11: FY 2026-27 | BS11: 4
